<?xml version="1.0" encoding="utf-8"?>
<!-- =================================================================================== -->
<!-- |    This document was autogenerated by xacro from jannat2.xacro                  | -->
<!-- |    EDITING THIS FILE BY HAND IS NOT RECOMMENDED                                 | -->
<!-- =================================================================================== -->
<robot name="jannat2">
  <material name="silver">
    <color rgba="0.700 0.700 0.700 1.000"/>
  </material>
  <transmission name="wheel1_jt_tran">
    <type>transmission_interface/SimpleTransmission</type>
    <joint name="wheel1_jt">
      <hardwareInterface>hardware_interface/EffortJointInterface</hardwareInterface>
    </joint>
    <actuator name="wheel1_jt_actr">
      <hardwareInterface>hardware_interface/EffortJointInterface</hardwareInterface>
      <mechanicalReduction>1</mechanicalReduction>
    </actuator>
  </transmission>
  <transmission name="wheel3_jt_tran">
    <type>transmission_interface/SimpleTransmission</type>
    <joint name="wheel3_jt">
      <hardwareInterface>hardware_interface/EffortJointInterface</hardwareInterface>
    </joint>
    <actuator name="wheel3_jt_actr">
      <hardwareInterface>hardware_interface/EffortJointInterface</hardwareInterface>
      <mechanicalReduction>1</mechanicalReduction>
    </actuator>
  </transmission>
  <transmission name="wheel2_jt_tran">
    <type>transmission_interface/SimpleTransmission</type>
    <joint name="wheel2_jt">
      <hardwareInterface>hardware_interface/EffortJointInterface</hardwareInterface>
    </joint>
    <actuator name="wheel2_jt_actr">
      <hardwareInterface>hardware_interface/EffortJointInterface</hardwareInterface>
      <mechanicalReduction>1</mechanicalReduction>
    </actuator>
  </transmission>
  <transmission name="wheel4_jt_tran">
    <type>transmission_interface/SimpleTransmission</type>
    <joint name="wheel4_jt">
      <hardwareInterface>hardware_interface/EffortJointInterface</hardwareInterface>
    </joint>
    <actuator name="wheel4_jt_actr">
      <hardwareInterface>hardware_interface/EffortJointInterface</hardwareInterface>
      <mechanicalReduction>1</mechanicalReduction>
    </actuator>
  </transmission>
  <gazebo reference="base_link">
    <material>Gazebo/White</material>
  </gazebo>
  <gazebo reference="wheel_1_1">
    <material>Gazebo/Grey</material>
  </gazebo>
  <gazebo reference="wheel_3_1">
    <material>Gazebo/Grey</material>
  </gazebo>
  <gazebo reference="wheel_2_1">
    <material>Gazebo/Grey</material>
  </gazebo>
  <gazebo reference="wheel_4_1">
    <material>Gazebo/Grey</material>
  </gazebo>
  <gazebo reference="lidar_1_1">
    <material>Gazebo/Black</material>
  </gazebo>
  <gazebo reference="base_link">
    <mu1>100</mu1>
    <mu2>100</mu2>
    <selfCollide>true</selfCollide>
    <gravity>true</gravity>
  </gazebo>
  <gazebo reference="wheel_1_1">
    <mu1>100</mu1>
    <mu2>100</mu2>
    <selfCollide>true</selfCollide>
  </gazebo>
  <gazebo reference="wheel_3_1">
    <mu1>100</mu1>
    <mu2>100</mu2>
    <selfCollide>true</selfCollide>
  </gazebo>
  <gazebo reference="wheel_2_1">
    <mu1>100</mu1>
    <mu2>100</mu2>
    <selfCollide>true</selfCollide>
  </gazebo>
  <gazebo reference="wheel_4_1">
    <mu1>100</mu1>
    <mu2>100</mu2>
    <selfCollide>true</selfCollide>
  </gazebo>
  <gazebo reference="lidar_1_1">
    <mu1>100</mu1>
    <mu2>100</mu2>
    <selfCollide>true</selfCollide>
  </gazebo>
  <gazebo>
    <plugin filename="libgazebo_ros_control.so" name="control"/>
  </gazebo>
  <gazebo>
    <plugin filename="libgazebo_ros_skid_steer_drive.so" name="skid_steer_drive_controller">
      <updateRate>100.0</updateRate>
      <robotNamespace>/</robotNamespace>
      <leftFrontJoint>wheel1_jt</leftFrontJoint>
      <rightFrontJoint>wheel2_jt</rightFrontJoint>
      <leftRearJoint>wheel3_jt</leftRearJoint>
      <rightRearJoint>wheel4_jt</rightRearJoint>
      <robotBaseFrame>base_link</robotBaseFrame>
      <torque>150</torque>
      <topicName>cmd_vel</topicName>
      <broadcastTF>false</broadcastTF>
    </plugin>
  </gazebo>
  <!-- hokuyo -->
  <gazebo reference="lidar_1_1">
    <sensor name="head_hokuyo_sensor" type="ray">
      <pose>0 0 0 0 0 0</pose>
      <visualize>true</visualize>
      <update_rate>40</update_rate>
      <ray>
        <scan>
          <horizontal>
            <samples>720</samples>
            <resolution>1</resolution>
            <min_angle>-1.570796</min_angle>
            <max_angle>1.570796</max_angle>
          </horizontal>
        </scan>
        <range>
          <min>0.10</min>
          <max>30.0</max>
          <resolution>0.01</resolution>
        </range>
        <noise>
          <type>gaussian</type>
          <!-- Noise parameters based on published spec for Hokuyo laser
               achieving "+-30mm" accuracy at range < 10m.  A mean of 0.0m and
               stddev of 0.01m will put 99.7% of samples within 0.03m of the true
               reading. -->
          <mean>0.0</mean>
          <stddev>0.01</stddev>
        </noise>
      </ray>
      <plugin filename="libgazebo_ros_laser.so" name="gazebo_ros_head_hokuyo_controller">
        <topicName>/scan</topicName>
        <frameName>lidar_1_1</frameName>
      </plugin>
    </sensor>
  </gazebo>
  <link name="base_link">
    <inertial>
      <origin rpy="0 0 0" xyz="-0.01821202435043162 1.756992283751737e-16 0.40253459213374404"/>
      <mass value="146.29832639048317"/>
      <inertia ixx="14.775068" ixy="-0.0" ixz="0.783456" iyy="17.891392" iyz="0.0" izz="10.567005"/>
    </inertial>
    <visual>
      <origin rpy="0 0 0" xyz="0 0 0"/>
      <geometry>
        <mesh filename="package://jannat2_description/meshes/base_link.stl" scale="0.001 0.001 0.001"/>
      </geometry>
      <material name="silver"/>
    </visual>
    <collision>
      <origin rpy="0 0 0" xyz="0 0 0"/>
      <geometry>
        <mesh filename="package://jannat2_description/meshes/base_link.stl" scale="0.001 0.001 0.001"/>
      </geometry>
    </collision>
  </link>
  <link name="wheel_1_1">
    <inertial>
      <origin rpy="0 0 0" xyz="0.0 0.06249999999999983 0.0"/>
      <mass value="17.809629848338286"/>
      <inertia ixx="0.162032" ixy="0.0" ixz="0.0" iyy="0.277686" iyz="0.0" izz="0.162032"/>
    </inertial>
    <visual>
      <origin rpy="0 0 0" xyz="-0.275 0.375 -0.175"/>
      <geometry>
        <mesh filename="package://jannat2_description/meshes/wheel_1_1.stl" scale="0.001 0.001 0.001"/>
      </geometry>
      <material name="silver"/>
    </visual>
    <collision>
      <origin rpy="0 0 0" xyz="-0.275 0.375 -0.175"/>
      <geometry>
        <mesh filename="package://jannat2_description/meshes/wheel_1_1.stl" scale="0.001 0.001 0.001"/>
      </geometry>
    </collision>
  </link>
  <link name="wheel_3_1">
    <inertial>
      <origin rpy="0 0 0" xyz="-5.551115123125783e-17 0.06249999999999983 -1.942890293094024e-16"/>
      <mass value="17.80962984833829"/>
      <inertia ixx="0.162032" ixy="-0.0" ixz="-0.0" iyy="0.277686" iyz="-0.0" izz="0.162032"/>
    </inertial>
    <visual>
      <origin rpy="0 0 0" xyz="0.275 0.375 -0.175"/>
      <geometry>
        <mesh filename="package://jannat2_description/meshes/wheel_3_1.stl" scale="0.001 0.001 0.001"/>
      </geometry>
      <material name="silver"/>
    </visual>
    <collision>
      <origin rpy="0 0 0" xyz="0.275 0.375 -0.175"/>
      <geometry>
        <mesh filename="package://jannat2_description/meshes/wheel_3_1.stl" scale="0.001 0.001 0.001"/>
      </geometry>
    </collision>
  </link>
  <link name="wheel_2_1">
    <inertial>
      <origin rpy="0 0 0" xyz="5.551115123125783e-17 -0.06249999999999983 -1.942890293094024e-16"/>
      <mass value="17.80962984833829"/>
      <inertia ixx="0.162032" ixy="-0.0" ixz="0.0" iyy="0.277686" iyz="0.0" izz="0.162032"/>
    </inertial>
    <visual>
      <origin rpy="0 0 0" xyz="-0.275 -0.375 -0.175"/>
      <geometry>
        <mesh filename="package://jannat2_description/meshes/wheel_2_1.stl" scale="0.001 0.001 0.001"/>
      </geometry>
      <material name="silver"/>
    </visual>
    <collision>
      <origin rpy="0 0 0" xyz="-0.275 -0.375 -0.175"/>
      <geometry>
        <mesh filename="package://jannat2_description/meshes/wheel_2_1.stl" scale="0.001 0.001 0.001"/>
      </geometry>
    </collision>
  </link>
  <link name="wheel_4_1">
    <inertial>
      <origin rpy="0 0 0" xyz="0.0 -0.06249999999999983 0.0"/>
      <mass value="17.809629848338286"/>
      <inertia ixx="0.162032" ixy="0.0" ixz="-0.0" iyy="0.277686" iyz="-0.0" izz="0.162032"/>
    </inertial>
    <visual>
      <origin rpy="0 0 0" xyz="0.275 -0.375 -0.175"/>
      <geometry>
        <mesh filename="package://jannat2_description/meshes/wheel_4_1.stl" scale="0.001 0.001 0.001"/>
      </geometry>
      <material name="silver"/>
    </visual>
    <collision>
      <origin rpy="0 0 0" xyz="0.275 -0.375 -0.175"/>
      <geometry>
        <mesh filename="package://jannat2_description/meshes/wheel_4_1.stl" scale="0.001 0.001 0.001"/>
      </geometry>
    </collision>
  </link>
  <link name="lidar_1_1">
    <inertial>
      <origin rpy="0 0 0" xyz="-2.7755575615628914e-17 9.046911093940672e-18 0.012499999999999956"/>
      <mass value="0.17907078125461814"/>
      <inertia ixx="8.1e-05" ixy="-0.0" ixz="0.0" iyy="8.1e-05" iyz="0.0" izz="0.000143"/>
    </inertial>
    <visual>
      <origin rpy="0 0 0" xyz="0.2 -0.0 -1.0"/>
      <geometry>
        <mesh filename="package://jannat2_description/meshes/lidar_1_1.stl" scale="0.001 0.001 0.001"/>
      </geometry>
      <material name="silver"/>
    </visual>
    <collision>
      <origin rpy="0 0 0" xyz="0.2 -0.0 -1.0"/>
      <geometry>
        <mesh filename="package://jannat2_description/meshes/lidar_1_1.stl" scale="0.001 0.001 0.001"/>
      </geometry>
    </collision>
  </link>
  <joint name="wheel1_jt" type="continuous">
    <origin rpy="0 0 0" xyz="0.275 -0.375 0.175"/>
    <parent link="base_link"/>
    <child link="wheel_1_1"/>
    <axis xyz="0.0 1.0 0.0"/>
  </joint>
  <joint name="wheel3_jt" type="continuous">
    <origin rpy="0 0 0" xyz="-0.275 -0.375 0.175"/>
    <parent link="base_link"/>
    <child link="wheel_3_1"/>
    <axis xyz="0.0 1.0 0.0"/>
  </joint>
  <joint name="wheel2_jt" type="continuous">
    <origin rpy="0 0 0" xyz="0.275 0.375 0.175"/>
    <parent link="base_link"/>
    <child link="wheel_2_1"/>
    <axis xyz="0.0 1.0 0.0"/>
  </joint>
  <joint name="wheel4_jt" type="continuous">
    <origin rpy="0 0 0" xyz="-0.275 0.375 0.175"/>
    <parent link="base_link"/>
    <child link="wheel_4_1"/>
    <axis xyz="0.0 1.0 0.0"/>
  </joint>
  <joint name="Rigid6" type="fixed">
    <origin rpy="0 0 0" xyz="-0.2 0.0 1.0"/>
    <parent link="base_link"/>
    <child link="lidar_1_1"/>
  </joint>
</robot>
